Traceback (most recent call last):
  File "/Users/olgascrivner/anaconda3/lib/python3.7/site-packages/jupyter_cache/executors/utils.py", line 56, in single_nb_execution
    record_timing=False,
  File "/Users/olgascrivner/anaconda3/lib/python3.7/site-packages/nbclient/client.py", line 1082, in execute
    return NotebookClient(nb=nb, resources=resources, km=km, **kwargs).execute()
  File "/Users/olgascrivner/anaconda3/lib/python3.7/site-packages/nbclient/util.py", line 74, in wrapped
    return just_run(coro(*args, **kwargs))
  File "/Users/olgascrivner/anaconda3/lib/python3.7/site-packages/nbclient/util.py", line 53, in just_run
    return loop.run_until_complete(coro)
  File "/Users/olgascrivner/anaconda3/lib/python3.7/asyncio/base_events.py", line 573, in run_until_complete
    return future.result()
  File "/Users/olgascrivner/anaconda3/lib/python3.7/site-packages/nbclient/client.py", line 536, in async_execute
    cell, index, execution_count=self.code_cells_executed + 1
  File "/Users/olgascrivner/anaconda3/lib/python3.7/site-packages/nbclient/client.py", line 827, in async_execute_cell
    self._check_raise_for_error(cell, exec_reply)
  File "/Users/olgascrivner/anaconda3/lib/python3.7/site-packages/nbclient/client.py", line 735, in _check_raise_for_error
    raise CellExecutionError.from_cell_and_msg(cell, exec_reply['content'])
nbclient.exceptions.CellExecutionError: An error occurred while executing the following cell:
------------------
r = redis.Redis(host='127.0.0.1', port=6379, db=0) #the object r is created
r.mset({"Croatia": "Zagreb", "Bahamas": "Nassau"})
r.get("Bahamas")
------------------

[0;31m---------------------------------------------------------------------------[0m
[0;31mConnectionRefusedError[0m                    Traceback (most recent call last)
[0;32m~/anaconda3/lib/python3.7/site-packages/redis/connection.py[0m in [0;36mconnect[0;34m(self)[0m
[1;32m    607[0m             sock = self.retry.call_with_retry(
[0;32m--> 608[0;31m                 [0;32mlambda[0m[0;34m:[0m [0mself[0m[0;34m.[0m[0m_connect[0m[0;34m([0m[0;34m)[0m[0;34m,[0m [0;32mlambda[0m [0merror[0m[0;34m:[0m [0mself[0m[0;34m.[0m[0mdisconnect[0m[0;34m([0m[0merror[0m[0;34m)[0m[0;34m[0m[0;34m[0m[0m
[0m[1;32m    609[0m             )

[0;32m~/anaconda3/lib/python3.7/site-packages/redis/retry.py[0m in [0;36mcall_with_retry[0;34m(self, do, fail)[0m
[1;32m     44[0m             [0;32mtry[0m[0;34m:[0m[0;34m[0m[0;34m[0m[0m
[0;32m---> 45[0;31m                 [0;32mreturn[0m [0mdo[0m[0;34m([0m[0;34m)[0m[0;34m[0m[0;34m[0m[0m
[0m[1;32m     46[0m             [0;32mexcept[0m [0mself[0m[0;34m.[0m[0m_supported_errors[0m [0;32mas[0m [0merror[0m[0;34m:[0m[0;34m[0m[0;34m[0m[0m

[0;32m~/anaconda3/lib/python3.7/site-packages/redis/connection.py[0m in [0;36m<lambda>[0;34m()[0m
[1;32m    607[0m             sock = self.retry.call_with_retry(
[0;32m--> 608[0;31m                 [0;32mlambda[0m[0;34m:[0m [0mself[0m[0;34m.[0m[0m_connect[0m[0;34m([0m[0;34m)[0m[0;34m,[0m [0;32mlambda[0m [0merror[0m[0;34m:[0m [0mself[0m[0;34m.[0m[0mdisconnect[0m[0;34m([0m[0merror[0m[0;34m)[0m[0;34m[0m[0;34m[0m[0m
[0m[1;32m    609[0m             )

[0;32m~/anaconda3/lib/python3.7/site-packages/redis/connection.py[0m in [0;36m_connect[0;34m(self)[0m
[1;32m    672[0m         [0;32mif[0m [0merr[0m [0;32mis[0m [0;32mnot[0m [0;32mNone[0m[0;34m:[0m[0;34m[0m[0;34m[0m[0m
[0;32m--> 673[0;31m             [0;32mraise[0m [0merr[0m[0;34m[0m[0;34m[0m[0m
[0m[1;32m    674[0m         [0;32mraise[0m [0mOSError[0m[0;34m([0m[0;34m"socket.getaddrinfo returned an empty list"[0m[0;34m)[0m[0;34m[0m[0;34m[0m[0m

[0;32m~/anaconda3/lib/python3.7/site-packages/redis/connection.py[0m in [0;36m_connect[0;34m(self)[0m
[1;32m    660[0m                 [0;31m# connect[0m[0;34m[0m[0;34m[0m[0;34m[0m[0m
[0;32m--> 661[0;31m                 [0msock[0m[0;34m.[0m[0mconnect[0m[0;34m([0m[0msocket_address[0m[0;34m)[0m[0;34m[0m[0;34m[0m[0m
[0m[1;32m    662[0m [0;34m[0m[0m

[0;31mConnectionRefusedError[0m: [Errno 61] Connection refused

During handling of the above exception, another exception occurred:

[0;31mConnectionError[0m                           Traceback (most recent call last)
[0;32m<ipython-input-4-c100dba408bd>[0m in [0;36m<module>[0;34m[0m
[1;32m      1[0m [0mr[0m [0;34m=[0m [0mredis[0m[0;34m.[0m[0mRedis[0m[0;34m([0m[0mhost[0m[0;34m=[0m[0;34m'127.0.0.1'[0m[0;34m,[0m [0mport[0m[0;34m=[0m[0;36m6379[0m[0;34m,[0m [0mdb[0m[0;34m=[0m[0;36m0[0m[0;34m)[0m [0;31m#the object r is created[0m[0;34m[0m[0;34m[0m[0m
[0;32m----> 2[0;31m [0mr[0m[0;34m.[0m[0mmset[0m[0;34m([0m[0;34m{[0m[0;34m"Croatia"[0m[0;34m:[0m [0;34m"Zagreb"[0m[0;34m,[0m [0;34m"Bahamas"[0m[0;34m:[0m [0;34m"Nassau"[0m[0;34m}[0m[0;34m)[0m[0;34m[0m[0;34m[0m[0m
[0m[1;32m      3[0m [0mr[0m[0;34m.[0m[0mget[0m[0;34m([0m[0;34m"Bahamas"[0m[0;34m)[0m[0;34m[0m[0;34m[0m[0m

[0;32m~/anaconda3/lib/python3.7/site-packages/redis/commands/core.py[0m in [0;36mmset[0;34m(self, mapping)[0m
[1;32m   1415[0m         [0;32mfor[0m [0mpair[0m [0;32min[0m [0mmapping[0m[0;34m.[0m[0mitems[0m[0;34m([0m[0;34m)[0m[0;34m:[0m[0;34m[0m[0;34m[0m[0m
[1;32m   1416[0m             [0mitems[0m[0;34m.[0m[0mextend[0m[0;34m([0m[0mpair[0m[0;34m)[0m[0;34m[0m[0;34m[0m[0m
[0;32m-> 1417[0;31m         [0;32mreturn[0m [0mself[0m[0;34m.[0m[0mexecute_command[0m[0;34m([0m[0;34m"MSET"[0m[0;34m,[0m [0;34m*[0m[0mitems[0m[0;34m)[0m[0;34m[0m[0;34m[0m[0m
[0m[1;32m   1418[0m [0;34m[0m[0m
[1;32m   1419[0m     [0;32mdef[0m [0mmsetnx[0m[0;34m([0m[0mself[0m[0;34m,[0m [0mmapping[0m[0;34m)[0m[0;34m:[0m[0;34m[0m[0;34m[0m[0m

[0;32m~/anaconda3/lib/python3.7/site-packages/redis/client.py[0m in [0;36mexecute_command[0;34m(self, *args, **options)[0m
[1;32m   1171[0m         [0mpool[0m [0;34m=[0m [0mself[0m[0;34m.[0m[0mconnection_pool[0m[0;34m[0m[0;34m[0m[0m
[1;32m   1172[0m         [0mcommand_name[0m [0;34m=[0m [0margs[0m[0;34m[[0m[0;36m0[0m[0;34m][0m[0;34m[0m[0;34m[0m[0m
[0;32m-> 1173[0;31m         [0mconn[0m [0;34m=[0m [0mself[0m[0;34m.[0m[0mconnection[0m [0;32mor[0m [0mpool[0m[0;34m.[0m[0mget_connection[0m[0;34m([0m[0mcommand_name[0m[0;34m,[0m [0;34m**[0m[0moptions[0m[0;34m)[0m[0;34m[0m[0;34m[0m[0m
[0m[1;32m   1174[0m [0;34m[0m[0m
[1;32m   1175[0m         [0;32mtry[0m[0;34m:[0m[0;34m[0m[0;34m[0m[0m

[0;32m~/anaconda3/lib/python3.7/site-packages/redis/connection.py[0m in [0;36mget_connection[0;34m(self, command_name, *keys, **options)[0m
[1;32m   1368[0m         [0;32mtry[0m[0;34m:[0m[0;34m[0m[0;34m[0m[0m
[1;32m   1369[0m             [0;31m# ensure this connection is connected to Redis[0m[0;34m[0m[0;34m[0m[0;34m[0m[0m
[0;32m-> 1370[0;31m             [0mconnection[0m[0;34m.[0m[0mconnect[0m[0;34m([0m[0;34m)[0m[0;34m[0m[0;34m[0m[0m
[0m[1;32m   1371[0m             [0;31m# connections that the pool provides should be ready to send[0m[0;34m[0m[0;34m[0m[0;34m[0m[0m
[1;32m   1372[0m             [0;31m# a command. if not, the connection was either returned to the[0m[0;34m[0m[0;34m[0m[0;34m[0m[0m

[0;32m~/anaconda3/lib/python3.7/site-packages/redis/connection.py[0m in [0;36mconnect[0;34m(self)[0m
[1;32m    611[0m             [0;32mraise[0m [0mTimeoutError[0m[0;34m([0m[0;34m"Timeout connecting to server"[0m[0;34m)[0m[0;34m[0m[0;34m[0m[0m
[1;32m    612[0m         [0;32mexcept[0m [0mOSError[0m [0;32mas[0m [0me[0m[0;34m:[0m[0;34m[0m[0;34m[0m[0m
[0;32m--> 613[0;31m             [0;32mraise[0m [0mConnectionError[0m[0;34m([0m[0mself[0m[0;34m.[0m[0m_error_message[0m[0;34m([0m[0me[0m[0;34m)[0m[0;34m)[0m[0;34m[0m[0;34m[0m[0m
[0m[1;32m    614[0m [0;34m[0m[0m
[1;32m    615[0m         [0mself[0m[0;34m.[0m[0m_sock[0m [0;34m=[0m [0msock[0m[0;34m[0m[0;34m[0m[0m

[0;31mConnectionError[0m: Error 61 connecting to 127.0.0.1:6379. Connection refused.
ConnectionError: Error 61 connecting to 127.0.0.1:6379. Connection refused.

